Workbook

Sheet Bronze
A1: Pedido | B1: Data | C1: Cliente | D1: Cidade | E1: Produto | F1: Valor (R$)
A2: 1001 | B2: 2026-01-01 | C2: Irrigação Vale Forte | D2: Petrolina | E2: Tubo galvanizado 2" | F2: 3260
A3: 1002 | B3: 46024 | C3: Grades Caruaru | D3: Caruaru | E3: Barra chata 1" | F3: 3570
A4: 1003 | B4: 46028 | C4: Serralheria Capibaribe | D4: recife | E4: Telha trapezoidal | F4: 1940
A5: 1004 | B5: 46029 | C5: Serralheria Capibaribe | D5: Recife | E5: Chapa de aço 3 mm | F5: 4910
A6: 1005 | B6: 2026-01-16 | C6: Agro Estruturas São Francisco | D6: Petrolina | E6: Perfil U enrijecido | F6: 4500
A7: 1006 | B7: 2026-01-27 | C7: Irrigação Vale Forte | D7: Petrolina | E7: Cantoneira 1/2" | F7: 1350
A8: 1007 | B8: 01-fev-2026 | C8: Grades Caruaru | D8: Caruaru | E8: Perfil U enrijecido | F8: 5360
A9: 1008 | B9: 46057 | C9: Estaleiro Porto Novo | D9: REC | E9: Cantoneira 1/2" | F9: 3900
A10: 1009 | B10: 46059 | C10: Serralheria Capibaribe | D10: Recife | E10: Barra chata 1" | F10: 4040
A11: 1010 | B11: 46060 | C11: Calhas Olinda | D11: Olinda | E11: Tubo galvanizado 2" | F11: 5700
A12: 1011 | B12: 46066 | C12: Calhas Olinda | D12: Olinda | E12: Chapa de aço 3 mm | F12: 4400
A13: 1012 | B13: 46068 | C13: Grades Caruaru | D13: Caruaru | E13: Tubo galvanizado 2" | F13: 4510
A14: 1013 | B14: 46069 | C14: Estaleiro Porto Novo | D14: Recife | E14: Perfil U enrijecido | F14: 2410
A15: 1014 | B15: 46070 | C15: Agro Estruturas São Francisco | D15: Petrolina | E15: Barra chata 1" | F15: R$ 630,00
A17: 1015 | B17: 2026-02-19 | C17: Grades Caruaru | D17: Caruaru | E17: Perfil U enrijecido | F17: 5160
A18: 1016 | B18: 46073 | C18: Serralheria Capibaribe | D18: REC | E18: Cantoneira 1/2" | F18: 2390
A19: 1017 | B19: 46076 | C19: Estruturas Piedade | D19: Jaboatão dos Guararapes | E19: Telha trapezoidal | F19: 3920
A20: 1018 | B20: 46078 | C20: Agro Estruturas São Francisco | D20: Petrolina | E20: Telha trapezoidal | F20: 3340
A21: 1019 | B21: 2026-02-26 | C21: Serralheria Capibaribe | D21: recife | E21: Chapa de aço 3 mm | F21: R$ 2.240,00
A22: 1020 | B22: 46079 | C22: Construtora Boa Vista | D22: Recife | E22: Cantoneira 1/2" | F22: 1260
A23: 1021 | B23: 2026-02-27 | C23: Irrigação Vale Forte | D23: Petrolina | E23: Telha trapezoidal | F23: 4800
A24: 1022 | B24: 2026-03-05 | C24: Estruturas Piedade | D24: Jaboatão dos Guararapes | E24: Barra chata 1" | F24: 2980
A25: 1015 | B25: 2026-02-19 | C25: Grades Caruaru | D25: Caruaru | E25: Perfil U enrijecido | F25: 5160
A26: 1023 | B26: 46086 | C26: Metalfer Agreste | D26: Caruaru | E26: Barra chata 1" | F26: 5960
A27: 1024 | B27: 46087 | C27: Irrigação Vale Forte | D27: Petrolina | E27: Chapa de aço 3 mm | F27: 1590
A28: 1025 | B28: 06-mar-2026 | C28: Serralheria Capibaribe | D28: REC | E28: Chapa de aço 3 mm | F28: R$ 2.140,00
A29: 1026 | B29: 46088 | C29: Esquadrias Recife Antigo | D29: Recife | E29: Tubo galvanizado 2" | F29: R$ 5.480,00
A30: 1027 | B30: 46091 | C30: Metalfer Agreste | D30: Caruaru | E30: Cantoneira 1/2" | F30: 440
A31: 1028 | B31: 46093 | C31: Indústria Guararapes | D31: Jaboatão dos Guararapes | E31: Perfil U enrijecido | F31: 4290
A32: 1029 | B32: 12-mar-2026 | C32: Estaleiro Porto Novo | D32: REC | E32: Perfil U enrijecido | F32: R$ 6.190,00
A33: 1027 | B33: 46091 | C33: Metalfer Agreste | D33: Caruaru | E33: Cantoneira 1/2" | F33: 440
A34: 1030 | B34: 46093 | C34: Metalfer Agreste | D34: Caruaru | E34: Chapa de aço 3 mm | F34: 1220
A36: 1023 | B36: 46086 | C36: Metalfer Agreste | D36: Caruaru | E36: Barra chata 1" | F36: 5960
A37: 1031 | B37: 2026-03-14 | C37: Estaleiro Porto Novo | D37: recife | E37: Perfil U enrijecido | F37: 2080
A38: 1032 | B38: 2026-03-14 | C38: Indústria Guararapes | D38: Jaboatão dos Guararapes | E38: Barra chata 1" | F38: 800
A39: 1033 | B39: 46096 | C39: Construtora Boa Vista | D39: recife | E39: Chapa de aço 3 mm | F39: 3340
A40: 1034 | B40: 15-mar-2026 | C40: Grades Caruaru | D40: Caruaru | E40: Chapa de aço 3 mm | F40: 4510
A41: 1035 | B41: 46097 | C41: Indústria Guararapes | D41: Jaboatão dos Guararapes | E41: Cantoneira 1/2" | F41: 1650
A42: 1036 | B42: 46097 | C42: Estruturas Piedade | D42: Jaboatão dos Guararapes | E42: Chapa de aço 3 mm | F42: 5350
...

Sheet Prata
A1: Pedido | B1: Data | C1: Cliente | D1: Cidade | E1: Produto | F1: Valor (R$) | G1: Mês
A2: 1001 | B2: 46023 | C2: Irrigação Vale Forte | D2: Petrolina | E2: Tubo galvanizado 2" | F2: 3260 | G2: 01/2026
A3: 1002 | B3: 46024 | C3: Grades Caruaru | D3: Caruaru | E3: Barra chata 1" | F3: 3570 | G3: 01/2026
A4: 1003 | B4: 46028 | C4: Serralheria Capibaribe | D4: Recife | E4: Telha trapezoidal | F4: 1940 | G4: 01/2026
A5: 1004 | B5: 46029 | C5: Serralheria Capibaribe | D5: Recife | E5: Chapa de aço 3 mm | F5: 4910 | G5: 01/2026
A6: 1005 | B6: 46038 | C6: Agro Estruturas São Francisco | D6: Petrolina | E6: Perfil U enrijecido | F6: 4500 | G6: 01/2026
A7: 1006 | B7: 46049 | C7: Irrigação Vale Forte | D7: Petrolina | E7: Cantoneira 1/2" | F7: 1350 | G7: 01/2026
A8: 1007 | B8: 46054 | C8: Grades Caruaru | D8: Caruaru | E8: Perfil U enrijecido | F8: 5360 | G8: 02/2026
A9: 1008 | B9: 46057 | C9: Estaleiro Porto Novo | D9: Recife | E9: Cantoneira 1/2" | F9: 3900 | G9: 02/2026
A10: 1009 | B10: 46059 | C10: Serralheria Capibaribe | D10: Recife | E10: Barra chata 1" | F10: 4040 | G10: 02/2026
A11: 1010 | B11: 46060 | C11: Calhas Olinda | D11: Olinda | E11: Tubo galvanizado 2" | F11: 5700 | G11: 02/2026
A12: 1011 | B12: 46066 | C12: Calhas Olinda | D12: Olinda | E12: Chapa de aço 3 mm | F12: 4400 | G12: 02/2026
A13: 1012 | B13: 46068 | C13: Grades Caruaru | D13: Caruaru | E13: Tubo galvanizado 2" | F13: 4510 | G13: 02/2026
... A54: 1053 | B54: 46138 | C54: Irrigação Vale Forte | D54: Petrolina | E54: Telha trapezoidal | F54: 3610 | G54: 04/2026

Sheet Ouro
A1: Cidade | B1: 01/2026 | C1: 02/2026 | D1: 03/2026 | E1: 04/2026 | F1: Total
A2: Caruaru | B2: =SUMIFS(Prata!$F$2:$F$54,Prata!$D$2:$D$54,$A2,Prata!$G$2:$G$54,B$1) -> 3570 | C2: =SUMIFS(Prata!$F$2:$F$54,Prata!$D$2:$D$54,$A2,Prata!$G$2:$G$54,C$1) -> 15030 | D2: =SUMIFS(Prata!$F$2:$F$54,Prata!$D$2:$D$54,$A2,Prata!$G$2:$G$54,D$1) -> 17610 | E2: =SUMIFS(Prata!$F$2:$F$54,Prata!$D$2:$D$54,$A2,Prata!$G$2:$G$54,E$1) -> 6930 | F2: =SUM(B2:E2) -> 43140
A3: Jaboatão dos Guararapes | B3: =SUMIFS(Prata!$F$2:$F$54,Prata!$D$2:$D$54,$A3,Prata!$G$2:$G$54,B$1) -> 0 | C3: =SUMIFS(Prata!$F$2:$F$54,Prata!$D$2:$D$54,$A3,Prata!$G$2:$G$54,C$1) -> 3920 | D3: =SUMIFS(Prata!$F$2:$F$54,Prata!$D$2:$D$54,$A3,Prata!$G$2:$G$54,D$1) -> 22820 | E3: =SUMIFS(Prata!$F$2:$F$54,Prata!$D$2:$D$54,$A3,Prata!$G$2:$G$54,E$1) -> 1120 | F3: =SUM(B3:E3) -> 27860
A4: Olinda | B4: =SUMIFS(Prata!$F$2:$F$54,Prata!$D$2:$D$54,$A4,Prata!$G$2:$G$54,B$1) -> 0 | C4: =SUMIFS(Prata!$F$2:$F$54,Prata!$D$2:$D$54,$A4,Prata!$G$2:$G$54,C$1) -> 10100 | D4: =SUMIFS(Prata!$F$2:$F$54,Prata!$D$2:$D$54,$A4,Prata!$G$2:$G$54,D$1) -> 7710 | E4: =SUMIFS(Prata!$F$2:$F$54,Prata!$D$2:$D$54,$A4,Prata!$G$2:$G$54,E$1) -> 11190 | F4: =SUM(B4:E4) -> 29000
A5: Petrolina | B5: =SUMIFS(Prata!$F$2:$F$54,Prata!$D$2:$D$54,$A5,Prata!$G$2:$G$54,B$1) -> 9110 | C5: =SUMIFS(Prata!$F$2:$F$54,Prata!$D$2:$D$54,$A5,Prata!$G$2:$G$54,C$1) -> 8770 | D5: =SUMIFS(Prata!$F$2:$F$54,Prata!$D$2:$D$54,$A5,Prata!$G$2:$G$54,D$1) -> 1590 | E5: =SUMIFS(Prata!$F$2:$F$54,Prata!$D$2:$D$54,$A5,Prata!$G$2:$G$54,E$1) -> 3610 | F5: =SUM(B5:E5) -> 23080
A6: Recife | B6: =SUMIFS(Prata!$F$2:$F$54,Prata!$D$2:$D$54,$A6,Prata!$G$2:$G$54,B$1) -> 6850 | C6: =SUMIFS(Prata!$F$2:$F$54,Prata!$D$2:$D$54,$A6,Prata!$G$2:$G$54,C$1) -> 16240 | D6: =SUMIFS(Prata!$F$2:$F$54,Prata!$D$2:$D$54,$A6,Prata!$G$2:$G$54,D$1) -> 29730 | E6: =SUMIFS(Prata!$F$2:$F$54,Prata!$D$2:$D$54,$A6,Prata!$G$2:$G$54,E$1) -> 2440 | F6: =SUM(B6:E6) -> 55260
A7: Total | B7: =SUM(B2:B6) -> 19530 | C7: =SUM(C2:C6) -> 54060 | D7: =SUM(D2:D6) -> 79460 | E7: =SUM(E2:E6) -> 25290 | F7: =SUM(F2:F6) -> 178340
A9: Resposta
A10: A cidade que mais comprou foi Recife, com R$ 55.260,00 no total (Caruaru vem em segundo, com R$ 43.140,00). O mês em que Recife mais comprou foi março de 2026 (R$ 29.730,00), que também foi o mês de maior faturamento geral (R$ 79.460,00).

Sheet Log
A1: O que encontrei | B1: O que fiz | C1: Linhas afetadas | D1: Justificativa (se houve dúvida)
A2: 3 linhas totalmente vazias e com as colunas em branco. | B2: Removi as 3 linhas | C2: Bronze: 16, 35, 53 | D2: Remover linhas vazias permite que a tabela seja mais legível.
A3: 4 pedidos duplicados (linhas idênticas em todas as colunas): pedido 1015, pedido 1027, pedido 1023 e pedido 1047. | B3: Removi a repetição e mantive a primeira ocorrência | C3: Bronze: 25, 33, 36, 61 | D3: Linhas 100% idênticas, é a mesma venda lançada duas vezes, portanto conta-las inflaria o faturamento. Conferi que nenhum nº de pedido se repete com dados diferentes.
A4: Datas em 3 formatos diferentes | B4: Converti tudo para data real e padronizei a exibição como DD/MM/AAAA | C4: Bronze: 2, 6, 7, 8, 17, 21, 23, 24, 28, 32, 37, 38, 40, 43, 45, 47, 56 (as que estavam como texto) | D4: As datas foram interpretadas e organizadas como dia-mês-ano, seguindo a sequência dos registros, para ficar no formato padrão utilizado no Brasil.
A5: Cidade escrita de 3 formas: "Recife", "recife" e "REC" | B5: Padronizei tudo como "Recife" | C5: Bronze: 4, 9, 18, 21, 28, 32, 37, 39, 51, 59 (as 5 "recife" e as 5 "REC") | D5: "recife" é diferença de maiúscula e minúscula, para padrozinar em uma tabela de negócios, optei pela norma culta. "REC" foi lido como sigla de Recife.
A6: Valores monetários digitados como texto. | B6: Removi "R$", tirei o ponto de milhar, troquei a vírgula decimal por ponto e converti para número | C6: Bronze: 15, 21, 28, 29, 32, 44, 51 | D6: Interpretei ponto como milhar e vírgula como decimal, que é o padrão BR: "R$ 2.240,00" = 2240. Conferi que os valores convertidos ficam na mesma faixa dos pedidos que já pertenciam.
A7: Para a aba Ouro, ainda faltava a coluna por mês na aba Prata. | B7: Acrescentei a coluna "Mês", calculada a partir da data já padronizada. | C7: Prata: coluna G, linhas 2 a 54
